<?xml version="1.0"?>
<robot name="diff_drive">

  <!-- =======================
       BASE LINK (GREY CHASSIS)
       ======================= -->
  <link name="base_link">
    <inertial>
      <origin xyz="0 0 0" rpy="0 0 0"/>
      <mass value="5"/>
      <inertia ixx="0.05" iyy="0.05" izz="0.08"
               ixy="0" ixz="0" iyz="0"/>
    </inertial>

    <visual>
      <origin xyz="0 0 0" rpy="0 0 0"/>
      <geometry>
        <box size="0.3 0.2 0.1"/>
      </geometry>
      <material name="grey">
        <color rgba="0.5 0.5 0.5 1"/>
      </material>
    </visual>

    <collision>
      <origin xyz="0 0 0" rpy="0 0 0"/>
      <geometry>
        <box size="0.3 0.2 0.1"/>
      </geometry>
    </collision>
  </link>


  <!-- =======================
       LEFT WHEEL (RED)
       ======================= -->
  <link name="left_wheel">
    <inertial>
      <origin xyz="0 0 0" rpy="0 0 0"/>
      <mass value="0.5"/>
      <inertia ixx="0.001" iyy="0.001" izz="0.0005"
               ixy="0" ixz="0" iyz="0"/>
    </inertial>

    <visual>
      <!-- Rotate cylinder so axis aligns with Y -->
      <origin xyz="0 0 0" rpy="1.5708 0 0"/>
      <geometry>
        <cylinder radius="0.05" length="0.04"/>
      </geometry>
      <material name="red">
        <color rgba="1 0 0 1"/>
      </material>
    </visual>

    <collision>
      <origin xyz="0 0 0" rpy="1.5708 0 0"/>
      <geometry>
        <cylinder radius="0.05" length="0.04"/>
      </geometry>
      <surface>
        <friction>
          <ode mu="1.0" mu2="1.0"/>
        </friction>
      </surface>
    </collision>
  </link>

  <joint name="left_wheel_joint" type="continuous">
    <parent link="base_link"/>
    <child link="left_wheel"/>
    <!-- Wheel center at z = -0.05 so bottom touches ground -->
    <origin xyz="0 0.1 -0.05" rpy="0 0 0"/>
    <axis xyz="0 1 0"/>
  </joint>


  <!-- =======================
       RIGHT WHEEL (GREEN)
       ======================= -->
  <link name="right_wheel">
    <inertial>
      <origin xyz="0 0 0" rpy="0 0 0"/>
      <mass value="0.5"/>
      <inertia ixx="0.001" iyy="0.001" izz="0.0005"
               ixy="0" ixz="0" iyz="0"/>
    </inertial>

    <visual>
      <origin xyz="0 0 0" rpy="1.5708 0 0"/>
      <geometry>
        <cylinder radius="0.05" length="0.04"/>
      </geometry>
      <material name="green">
        <color rgba="0 1 0 1"/>
      </material>
    </visual>

    <collision>
      <origin xyz="0 0 0" rpy="1.5708 0 0"/>
      <geometry>
        <cylinder radius="0.05" length="0.04"/>
      </geometry>
      <surface>
        <friction>
          <ode mu="1.0" mu2="1.0"/>
        </friction>
      </surface>
    </collision>
  </link>

  <joint name="right_wheel_joint" type="continuous">
    <parent link="base_link"/>
    <child link="right_wheel"/>
    <origin xyz="0 -0.1 -0.05" rpy="0 0 0"/>
    <axis xyz="0 1 0"/>
  </joint>

</robot>